[2025-01-24T18:30:03.756+0000] {taskinstance.py:1159} INFO - Dependencies all met for dep_context=non-requeueable deps ti=<TaskInstance: s3_to_redshift_copy_command.load_data_to_redshift manual__2025-01-24T18:30:01.909445+00:00 [queued]>
[2025-01-24T18:30:03.762+0000] {taskinstance.py:1159} INFO - Dependencies all met for dep_context=requeueable deps ti=<TaskInstance: s3_to_redshift_copy_command.load_data_to_redshift manual__2025-01-24T18:30:01.909445+00:00 [queued]>
[2025-01-24T18:30:03.762+0000] {taskinstance.py:1361} INFO - Starting attempt 1 of 2
[2025-01-24T18:30:03.771+0000] {taskinstance.py:1382} INFO - Executing <Task(PythonOperator): load_data_to_redshift> on 2025-01-24 18:30:01.909445+00:00
[2025-01-24T18:30:03.780+0000] {standard_task_runner.py:57} INFO - Started process 212 to run task
[2025-01-24T18:30:03.784+0000] {standard_task_runner.py:84} INFO - Running: ['***', 'tasks', 'run', 's3_to_redshift_copy_command', 'load_data_to_redshift', 'manual__2025-01-24T18:30:01.909445+00:00', '--job-id', '11', '--raw', '--subdir', 'DAGS_FOLDER/load_user.py', '--cfg-path', '/tmp/tmpt0am_y_7']
[2025-01-24T18:30:03.787+0000] {standard_task_runner.py:85} INFO - Job 11: Subtask load_data_to_redshift
[2025-01-24T18:30:03.822+0000] {logging_mixin.py:151} WARNING - /home/***/.local/lib/python3.8/site-packages/***/settings.py:195 DeprecationWarning: The sql_alchemy_conn option in [core] has been moved to the sql_alchemy_conn option in [database] - the old setting has been used, but please update your config.
[2025-01-24T18:30:03.858+0000] {task_command.py:415} INFO - Running <TaskInstance: s3_to_redshift_copy_command.load_data_to_redshift manual__2025-01-24T18:30:01.909445+00:00 [running]> on host 62f96838568e
[2025-01-24T18:30:03.965+0000] {taskinstance.py:1660} INFO - Exporting env vars: AIRFLOW_CTX_DAG_OWNER='***' AIRFLOW_CTX_DAG_ID='s3_to_redshift_copy_command' AIRFLOW_CTX_TASK_ID='load_data_to_redshift' AIRFLOW_CTX_EXECUTION_DATE='2025-01-24T18:30:01.909445+00:00' AIRFLOW_CTX_TRY_NUMBER='1' AIRFLOW_CTX_DAG_RUN_ID='manual__2025-01-24T18:30:01.909445+00:00'
[2025-01-24T18:30:03.988+0000] {base.py:73} INFO - Using connection ID 'redshift_default' for task execution.
[2025-01-24T18:30:04.144+0000] {sql.py:418} INFO - Running statement: 
    COPY dev.user_details
    FROM 's3://datalakepax8/external/user_data.json'
    IAM_ROLE 'arn:aws:iam::654654432597:role/s3-access-to-redshift'  -- Replace with your IAM role ARN if necessary
    ACCESS_KEY_ID 'AKIAZQ3DR4VKSDXA6OEJ'
    SECRET_ACCESS_KEY 'rQI9COcUQdvA0mqE5HMoQ337TpmkLGe3CLzuNRd1'
    FORMAT AS JSON 'auto'
    IGNOREHEADER 1;  -- Add additional options based on your file format
    , parameters: None
[2025-01-24T18:30:19.078+0000] {taskinstance.py:1943} ERROR - Task failed with exception
Traceback (most recent call last):
  File "/home/airflow/.local/lib/python3.8/site-packages/airflow/operators/python.py", line 192, in execute
    return_value = self.execute_callable()
  File "/home/airflow/.local/lib/python3.8/site-packages/airflow/operators/python.py", line 209, in execute_callable
    return self.python_callable(*self.op_args, **self.op_kwargs)
  File "/opt/airflow/dags/load_user.py", line 27, in run_copy_command
    redshift_hook.run(copy_sql)
  File "/home/airflow/.local/lib/python3.8/site-packages/airflow/providers/common/sql/hooks/sql.py", line 392, in run
    self._run_command(cur, sql_statement, parameters)
  File "/home/airflow/.local/lib/python3.8/site-packages/airflow/providers/common/sql/hooks/sql.py", line 423, in _run_command
    cur.execute(sql_statement)
psycopg2.errors.InvalidSchemaName: schema "dev" does not exist

[2025-01-24T18:30:19.125+0000] {taskinstance.py:1400} INFO - Marking task as UP_FOR_RETRY. dag_id=s3_to_redshift_copy_command, task_id=load_data_to_redshift, execution_date=20250124T183001, start_date=20250124T183003, end_date=20250124T183019
[2025-01-24T18:30:19.143+0000] {standard_task_runner.py:104} ERROR - Failed to execute job 11 for task load_data_to_redshift (schema "dev" does not exist
; 212)
[2025-01-24T18:30:19.167+0000] {local_task_job_runner.py:228} INFO - Task exited with return code 1
[2025-01-24T18:30:19.191+0000] {taskinstance.py:2784} INFO - 0 downstream tasks scheduled from follow-on schedule check
