[2025-01-24T18:02:38.285+0000] {taskinstance.py:1159} INFO - Dependencies all met for dep_context=non-requeueable deps ti=<TaskInstance: copy_s3_to_redshift_callable.load_data_to_redshift manual__2025-01-24T18:02:33.406891+00:00 [queued]>
[2025-01-24T18:02:38.291+0000] {taskinstance.py:1159} INFO - Dependencies all met for dep_context=requeueable deps ti=<TaskInstance: copy_s3_to_redshift_callable.load_data_to_redshift manual__2025-01-24T18:02:33.406891+00:00 [queued]>
[2025-01-24T18:02:38.291+0000] {taskinstance.py:1361} INFO - Starting attempt 1 of 2
[2025-01-24T18:02:38.310+0000] {taskinstance.py:1382} INFO - Executing <Task(PythonOperator): load_data_to_redshift> on 2025-01-24 18:02:33.406891+00:00
[2025-01-24T18:02:38.333+0000] {standard_task_runner.py:84} INFO - Running: ['***', 'tasks', 'run', 'copy_s3_to_redshift_callable', 'load_data_to_redshift', 'manual__2025-01-24T18:02:33.406891+00:00', '--job-id', '8', '--raw', '--subdir', 'DAGS_FOLDER/load_user.py', '--cfg-path', '/tmp/tmphulwf3rm']
[2025-01-24T18:02:38.331+0000] {standard_task_runner.py:57} INFO - Started process 194 to run task
[2025-01-24T18:02:38.338+0000] {standard_task_runner.py:85} INFO - Job 8: Subtask load_data_to_redshift
[2025-01-24T18:02:38.400+0000] {logging_mixin.py:151} WARNING - /home/***/.local/lib/python3.8/site-packages/***/settings.py:195 DeprecationWarning: The sql_alchemy_conn option in [core] has been moved to the sql_alchemy_conn option in [database] - the old setting has been used, but please update your config.
[2025-01-24T18:02:38.449+0000] {task_command.py:415} INFO - Running <TaskInstance: copy_s3_to_redshift_callable.load_data_to_redshift manual__2025-01-24T18:02:33.406891+00:00 [running]> on host 789d19555d0d
[2025-01-24T18:02:38.588+0000] {taskinstance.py:1660} INFO - Exporting env vars: AIRFLOW_CTX_DAG_OWNER='***' AIRFLOW_CTX_DAG_ID='copy_s3_to_redshift_callable' AIRFLOW_CTX_TASK_ID='load_data_to_redshift' AIRFLOW_CTX_EXECUTION_DATE='2025-01-24T18:02:33.406891+00:00' AIRFLOW_CTX_TRY_NUMBER='1' AIRFLOW_CTX_DAG_RUN_ID='manual__2025-01-24T18:02:33.406891+00:00'
[2025-01-24T18:02:38.592+0000] {taskinstance.py:1943} ERROR - Task failed with exception
Traceback (most recent call last):
  File "/home/airflow/.local/lib/python3.8/site-packages/airflow/operators/python.py", line 192, in execute
    return_value = self.execute_callable()
  File "/home/airflow/.local/lib/python3.8/site-packages/airflow/operators/python.py", line 209, in execute_callable
    return self.python_callable(*self.op_args, **self.op_kwargs)
  File "/opt/airflow/dags/load_user.py", line 11, in load_s3_to_redshift
    s3_hook.client = s3_hook.get_client_type("s3", login=aws_access_key_id, password=aws_secret_access_key)
TypeError: get_client_type() got an unexpected keyword argument 'login'
[2025-01-24T18:02:38.610+0000] {taskinstance.py:1400} INFO - Marking task as UP_FOR_RETRY. dag_id=copy_s3_to_redshift_callable, task_id=load_data_to_redshift, execution_date=20250124T180233, start_date=20250124T180238, end_date=20250124T180238
[2025-01-24T18:02:38.624+0000] {standard_task_runner.py:104} ERROR - Failed to execute job 8 for task load_data_to_redshift (get_client_type() got an unexpected keyword argument 'login'; 194)
[2025-01-24T18:02:38.663+0000] {local_task_job_runner.py:228} INFO - Task exited with return code 1
[2025-01-24T18:02:38.679+0000] {taskinstance.py:2784} INFO - 0 downstream tasks scheduled from follow-on schedule check
